Workbook

Sheet City ​​of Madrid
B2: Company | C2: Type | D2: Infrastructure | E2: Type Infrastructure | F2: City | G2: Zip Code | H2: Location | I2: Address | J2: Latitude | K2: Longitude
B4: InPost | C4: Lockers | D4: Private | E4: Supermarket | F4: Madrid | G4: 28001 | H4: Supermercado Dia | I4: Calle de Nuñez de Balboa, 32 | J4: 40.425934 | K4: -3.6820859
B5: InPost | C5: Lockers | D5: Private | E5: Parking | F5: Madrid | G5: 28001 | H5: 24/7 Parking Ayala Grupo | I5: Cl. de Ayala, 38 | J5: 40.427876 | K5: -3.6845761
B6: InPost | C6: Convenience stores | D6: Private | E6: Premises | F6: Madrid | G6: 28001 | H6: Grupo Hicorsa Artes Graficas | I6: Calle de Goya, 43 | J6: 40.425425 | K6: -3.6829045
B7: InPost | C7: Convenience stores | D7: Private | E7: Premises | F7: Madrid | G7: 28001 | H7: Panaderia Alimentacion Lagasca | I7: Calle de Lagasca, 6 | J7: 40.421287 | K7: -3.6855704
B8: InPost | C8: Convenience stores | D8: Private | E8: Premises | F8: Madrid | G8: 28001 | H8: Jesus Rodriguez Cuadros | I8: C. de Alcalá, 99 | J8: 40.421684 | K8: -3.683567
B9: InPost | C9: Convenience stores | D9: Private | E9: Premises | F9: Madrid | G9: 28001 | H9: La Capital | I9: Calle del Gral. Pardiñas, 3 | J9: 40.424026 | K9: -3.6788843
B10: InPost | C10: Convenience stores | D10: Private | E10: Premises | F10: Madrid | G10: 28001 | H10: Take Up | I10: Calle del Gral. Pardiñas, 31 | J10: 40.427107 | K10: -3.6787459
B11: InPost | C11: Lockers | D11: Public | E11: Parking | F11: Madrid | G11: 28001 | H11: 24/7 Emt Parking Recoletos | I11: P.º de Recoletos, 4 | J11: 40.420739 | K11: -3.6918522
B12: InPost | C12: Lockers | D12: Private | E12: Supermarket | F12: Madrid | G12: 28002 | H12: Locker Eroski City Sanchez Pach | I12: C. de Sánchez Pacheco | J12: 40.447746 | K12: -3.6723477
B13: InPost | C13: Convenience stores | D13: Private | E13: Premises | F13: Madrid | G13: 28002 | H13: Moran Opticos | I13: C. de López de Hoyos, 128 | J13: 40.445154 | K13: -3.6734021
B14: InPost | C14: Convenience stores | D14: Private | E14: Premises | F14: Madrid | G14: 28002 | H14: Herbolario Sana Sana | I14: C. de Pradillo, 7 | J14: 40.44896 | K14: -3.6754966
B15: InPost | C15: Convenience stores | D15: Private | E15: Premises | F15: Madrid | G15: 28002 | H15: Locutorio Robert Multiservices | I15: C. de Vinaroz, 2 | J15: 40.444972 | K15: -3.6750507
B16: InPost | C16: Convenience stores | D16: Private | E16: Premises | F16: Madrid | G16: 28002 | H16: Optica Golf | I16: C. del Príncipe de Vergara 2 | J16: 40.441907 | K16: -3.6785344
B17: InPost | C17: Lockers | D17: Private | E17: Supermarket | F17: Madrid | G17: 28002 | H17: Supermercado Dia | I17: C. de Eugenio Salazar, 27 | J17: 40.446448 | K17: -3.6748581
B18: InPost | C18: Convenience stores | D18: Private | E18: Premises | F18: Madrid | G18: 28002 | H18: Mioptico Lopez De Hoyos | I18: C. de López de Hoyos, 135 | J18: 40.447289 | K18: -3.6697828
... B28: InPost | C28: Convenience stores | D28: Private | E28: Premises | F28: Madrid | G28: 28003 | H28: La Tienda De Almudena | I28: Calle de Zurbano, 93 | J28: 40.44094 | K28: -3.6927401
B29: InPost | C29: Convenience stores | D29: Private | E29: Premises | F29: Madrid | G29: 28003 | H29: Mis Miss | I29: C. de Alonso Cano, 91 | J29: 40.444357 | K29: -3.6973242
B30: InPost | C30: Convenience stores | D30: Private | E30: Premises | F30: Madrid | G30: 28003 | H30: Baez Locutorio | I30: C. de Espronceda, 9 | J30: 40.441101 | K30: -3.698141
B31: InPost | C31: Convenience stores | D31: Private | E31: Premises | F31: Madrid | G31: 28003 | H31: Barullo Company | I31: Calle de Sta Engracia, 131 | J31: 40.442444 | K31: -3.702151
B32: InPost | C32: Convenience stores | D32: Private | E32: Premises | F32: Madrid | G32: 28003 | H32: Expendeduria 791 | I32: C/ de Ponzano, 25 | J32: 40.439226 | K32: -3.699629
B33: InPost | C33: Lockers | D33: Private | E33: Parking | F33: Madrid | G33: 28003 | H33: Locker 24/7 Parking Empark Ponz | I33: C. de Alenza, 18 | J33: 40.444416 | K33: -3.7004759
B34: InPost | C34: Lockers | D34: Private | E34: Premises | F34: Madrid | G34: 28003 | H34: Money Exchang | I34: C. de Raimundo Fernández Villaverde, 13 | J34: 40.447222 | K34: -3.7021532
B35: InPost | C35: Convenience stores | D35: Private | E35: Premises | F35: Madrid | G35: 28003 | H35: Bicicletas Y Calzado | I35: Av. de la Reina Victoria, 51 | J35: 40.446443 | K35: -3.7120553
B36: InPost | C36: Convenience stores | D36: Private | E36: Premises | F36: Madrid | G36: 28004 | H36: Nails Nactory Santa Barbara | I36: C. de Sta. Bárbara, 7 | J36: 40.424252 | K36: -3.7012663
B37: InPost | C37: Convenience stores | D37: Private | E37: Premises | F37: Madrid | G37: 28004 | H37: El Jardin De Churruca | I37: C. de Churruca, 19 | J37: 40.428212 | K37: -3.701358
B38: InPost | C38: Convenience stores | D38: Private | E38: Premises | F38: Madrid | G38: 28004 | H38: Dirtypop | I38: C. de Gravina, 1 | J38: 40.423612 | K38: -3.6985475
B39: InPost | C39: Convenience stores | D39: Private | E39: Premises | F39: Madrid | G39: 28004 | H39: Fotocopias Javipar | I39: C. de Loreto y Chicote, 13 | J39: 40.421742 | K39: -3.7044434
B40: InPost | C40: Convenience stores | D40: Private | E40: Premises | F40: Madrid | G40: 28004 | H40: Ixion Man | I40: C. de Pelayo, 9 | J40: 40.422519 | K40: -3.6991006
B41: InPost | C41: Convenience stores | D41: Private | E41: Premises | F41: Madrid | G41: 28004 | H41: El Jardin De Kika | I41: C. del Pez, 12 | J41: 40.423535 | K41: -3.7047451
B42: InPost | C42: Convenience stores | D42: Private | E42: Premises | F42: Madrid | G42: 28004 | H42: Copypez 12 | I42: C. del Pez, 12 | J42: 40.423629 | K42: -3.7048692
B43: InPost | C43: Lockers | D43: Private | E43: Parking | F43: Madrid | G43: 28004 | H43: 24/7 Parking Apk2 Plaza | I43: Plaza del Rey s/n | J43: 40.420326 | K43: -3.6961696
B44: InPost | C44: Convenience stores | D44: Private | E44: Premises | F44: Madrid | G44: 28004 | H44: The Mad Plug | I44: C. de Valverde, 35 | J44: 40.423223 | K44: -3.7018485
B45: InPost | C45: Convenience stores | D45: Private | E45: Premises | F45: Madrid | G45: 28004 | H45: Pcservice | I45: Cl. del Marqués de Sta. Ana | J45: 40.424638 | K45: -3.7049473
B46: InPost | C46: Lockers | D46: Private | E46: Premises | F46: Madrid | G46: 28004 | H46: Money Exchange Fuencarral | I46: Calle de Fuencarral & C. de las Infantas | J46: 40.421388 | K46: -3.7012384
B47: InPost | C47: Convenience stores | D47: Private | E47: Parking | F47: Madrid | G47: 28005 | H47: Locker Parking Latina | I47: C. de Toledo, 88 | J47: 40.408826 | K47: -3.7109194
B48: InPost | C48: Convenience stores | D48: Private | E48: Premises | F48: Madrid | G48: 28005 | H48: Golochuches | I48: C. de Melilla, 39 | J48: 40.400647 | K48: -3.7103177
B49: InPost | C49: Convenience stores | D49: Private | E49: Premises | F49: Madrid | G49: 28005 | H49: Estanco Piramides | I49: P.º de las Acacias, 69 | J49: 40.401131 | K49: -3.7132209
B50: InPost | C50: Convenience stores | D50: Private | E50: Premises | F50: Madrid | G50: 28005 | H50: Nuvole Di Profumo Mercado De La | I50: Pl. de la Cebada, S/N | J50: 40.41121 | K50: -3.7099362
B51: InPost | C51: Convenience stores | D51: Private | E51: Premises | F51: Madrid | G51: 28005 | H51: Optica Piramides | I51: P.º de Juan Antonio Vallejo-Nájera Botas | J51: 40.402114 | K51: -3.7080329
...

Sheet Sheet1
A1: Company | B1: Type | C1: Infrastructure | D1: Type Infrastructure | E1: City | F1: Zip Code | G1: Location | H1: Address | I1: Latitude | J1: Longitude | N1: Type | O1: Count of Infrastructure
A2: InPost | B2: Lockers | C2: Private | D2: Supermarket | E2: Madrid | F2: 28001 | G2: Supermercado Dia | H2: Calle de Nuñez de Balboa, 32 | I2: 40.425934 | J2: -3.6820859 | N2: Click&Collect | O2: 155
A3: InPost | B3: Lockers | C3: Private | D3: Parking | E3: Madrid | F3: 28001 | G3: 24/7 Parking Ayala Grupo | H3: Cl. de Ayala, 38 | I3: 40.427876 | J3: -3.6845761 | N3: Convenience stores | O3: 2207
A4: InPost | B4: Convenience stores | C4: Private | D4: Premises | E4: Madrid | F4: 28001 | G4: Grupo Hicorsa Artes Graficas | H4: Calle de Goya, 43 | I4: 40.425425 | J4: -3.6829045 | N4: Lockers | O4: 693
A5: InPost | B5: Convenience stores | C5: Private | D5: Premises | E5: Madrid | F5: 28001 | G5: Panaderia Alimentacion Lagasca | H5: Calle de Lagasca, 6 | I5: 40.421287 | J5: -3.6855704 | N5: LSP PUDOs | O5: 196
A6: InPost | B6: Convenience stores | C6: Private | D6: Premises | E6: Madrid | F6: 28001 | G6: Jesus Rodriguez Cuadros | H6: C. de Alcalá, 99 | I6: 40.421684 | J6: -3.683567 | N6: (en blanco) | O6: 1
A7: InPost | B7: Convenience stores | C7: Private | D7: Premises | E7: Madrid | F7: 28001 | G7: La Capital | H7: Calle del Gral. Pardiñas, 3 | I7: 40.424026 | J7: -3.6788843 | N7: Total general | O7: 3252
A8: InPost | B8: Convenience stores | C8: Private | D8: Premises | E8: Madrid | F8: 28001 | G8: Take Up | H8: Calle del Gral. Pardiñas, 31 | I8: 40.427107 | J8: -3.6787459
A9: InPost | B9: Lockers | C9: Public | D9: Parking | E9: Madrid | F9: 28001 | G9: 24/7 Emt Parking Recoletos | H9: P.º de Recoletos, 4 | I9: 40.420739 | J9: -3.6918522
A10: InPost | B10: Lockers | C10: Private | D10: Supermarket | E10: Madrid | F10: 28002 | G10: Locker Eroski City Sanchez Pach | H10: C. de Sánchez Pacheco | I10: 40.447746 | J10: -3.6723477
A11: InPost | B11: Convenience stores | C11: Private | D11: Premises | E11: Madrid | F11: 28002 | G11: Moran Opticos | H11: C. de López de Hoyos, 128 | I11: 40.445154 | J11: -3.6734021
A12: InPost | B12: Convenience stores | C12: Private | D12: Premises | E12: Madrid | F12: 28002 | G12: Herbolario Sana Sana | H12: C. de Pradillo, 7 | I12: 40.44896 | J12: -3.6754966
A13: InPost | B13: Convenience stores | C13: Private | D13: Premises | E13: Madrid | F13: 28002 | G13: Locutorio Robert Multiservices | H13: C. de Vinaroz, 2 | I13: 40.444972 | J13: -3.6750507
A14: InPost | B14: Convenience stores | C14: Private | D14: Premises | E14: Madrid | F14: 28002 | G14: Optica Golf | H14: C. del Príncipe de Vergara 2 | I14: 40.441907 | J14: -3.6785344
A15: InPost | B15: Lockers | C15: Private | D15: Supermarket | E15: Madrid | F15: 28002 | G15: Supermercado Dia | H15: C. de Eugenio Salazar, 27 | I15: 40.446448 | J15: -3.6748581
A16: InPost | B16: Convenience stores | C16: Private | D16: Premises | E16: Madrid | F16: 28002 | G16: Mioptico Lopez De Hoyos | H16: C. de López de Hoyos, 135 | I16: 40.447289 | J16: -3.6697828
A17: InPost | B17: Convenience stores | C17: Private | D17: Premises | E17: Madrid | F17: 28002 | G17: Digital Y Envios | H17: C/ de Baeza, 4 | I17: 40.445614 | J17: -3.6692721
A18: InPost | B18: Convenience stores | C18: Private | D18: Premises | E18: Madrid | F18: 28002 | G18: Luisipo | H18: C. de Clara del Rey, 2 | I18: 40.440245 | J18: -3.6735521
A19: InPost | B19: Lockers | C19: Private | D19: Parking | E19: Madrid | F19: 28002 | G19: Parking Clara Del Rey | H19: C. de Clara del Rey, 32 | I19: 40.443403 | J19: -3.6687157
... A26: InPost | B26: Convenience stores | C26: Private | D26: Premises | E26: Madrid | F26: 28003 | G26: La Tienda De Almudena | H26: Calle de Zurbano, 93 | I26: 40.44094 | J26: -3.6927401
A27: InPost | B27: Convenience stores | C27: Private | D27: Premises | E27: Madrid | F27: 28003 | G27: Mis Miss | H27: C. de Alonso Cano, 91 | I27: 40.444357 | J27: -3.6973242
A28: InPost | B28: Convenience stores | C28: Private | D28: Premises | E28: Madrid | F28: 28003 | G28: Baez Locutorio | H28: C. de Espronceda, 9 | I28: 40.441101 | J28: -3.698141
A29: InPost | B29: Convenience stores | C29: Private | D29: Premises | E29: Madrid | F29: 28003 | G29: Barullo Company | H29: Calle de Sta Engracia, 131 | I29: 40.442444 | J29: -3.702151
A30: InPost | B30: Convenience stores | C30: Private | D30: Premises | E30: Madrid | F30: 28003 | G30: Expendeduria 791 | H30: C/ de Ponzano, 25 | I30: 40.439226 | J30: -3.699629
A31: InPost | B31: Lockers | C31: Private | D31: Parking | E31: Madrid | F31: 28003 | G31: Locker 24/7 Parking Empark Ponz | H31: C. de Alenza, 18 | I31: 40.444416 | J31: -3.7004759
A32: InPost | B32: Lockers | C32: Private | D32: Premises | E32: Madrid | F32: 28003 | G32: Money Exchang | H32: C. de Raimundo Fernández Villaverde, 13 | I32: 40.447222 | J32: -3.7021532
A33: InPost | B33: Convenience stores | C33: Private | D33: Premises | E33: Madrid | F33: 28003 | G33: Bicicletas Y Calzado | H33: Av. de la Reina Victoria, 51 | I33: 40.446443 | J33: -3.7120553
A34: InPost | B34: Convenience stores | C34: Private | D34: Premises | E34: Madrid | F34: 28004 | G34: Nails Nactory Santa Barbara | H34: C. de Sta. Bárbara, 7 | I34: 40.424252 | J34: -3.7012663
A35: InPost | B35: Convenience stores | C35: Private | D35: Premises | E35: Madrid | F35: 28004 | G35: El Jardin De Churruca | H35: C. de Churruca, 19 | I35: 40.428212 | J35: -3.701358
A36: InPost | B36: Convenience stores | C36: Private | D36: Premises | E36: Madrid | F36: 28004 | G36: Dirtypop | H36: C. de Gravina, 1 | I36: 40.423612 | J36: -3.6985475
A37: InPost | B37: Convenience stores | C37: Private | D37: Premises | E37: Madrid | F37: 28004 | G37: Fotocopias Javipar | H37: C. de Loreto y Chicote, 13 | I37: 40.421742 | J37: -3.7044434
A38: InPost | B38: Convenience stores | C38: Private | D38: Premises | E38: Madrid | F38: 28004 | G38: Ixion Man | H38: C. de Pelayo, 9 | I38: 40.422519 | J38: -3.6991006
A39: InPost | B39: Convenience stores | C39: Private | D39: Premises | E39: Madrid | F39: 28004 | G39: El Jardin De Kika | H39: C. del Pez, 12 | I39: 40.423535 | J39: -3.7047451
A40: InPost | B40: Convenience stores | C40: Private | D40: Premises | E40: Madrid | F40: 28004 | G40: Copypez 12 | H40: C. del Pez, 12 | I40: 40.423629 | J40: -3.7048692
A41: InPost | B41: Lockers | C41: Private | D41: Parking | E41: Madrid | F41: 28004 | G41: 24/7 Parking Apk2 Plaza | H41: Plaza del Rey s/n | I41: 40.420326 | J41: -3.6961696
A42: InPost | B42: Convenience stores | C42: Private | D42: Premises | E42: Madrid | F42: 28004 | G42: The Mad Plug | H42: C. de Valverde, 35 | I42: 40.423223 | J42: -3.7018485
A43: InPost | B43: Convenience stores | C43: Private | D43: Premises | E43: Madrid | F43: 28004 | G43: Pcservice | H43: Cl. del Marqués de Sta. Ana | I43: 40.424638 | J43: -3.7049473
A44: InPost | B44: Lockers | C44: Private | D44: Premises | E44: Madrid | F44: 28004 | G44: Money Exchange Fuencarral | H44: Calle de Fuencarral & C. de las Infantas | I44: 40.421388 | J44: -3.7012384
A45: InPost | B45: Convenience stores | C45: Private | D45: Parking | E45: Madrid | F45: 28005 | G45: Locker Parking Latina | H45: C. de Toledo, 88 | I45: 40.408826 | J45: -3.7109194
A46: InPost | B46: Convenience stores | C46: Private | D46: Premises | E46: Madrid | F46: 28005 | G46: Golochuches | H46: C. de Melilla, 39 | I46: 40.400647 | J46: -3.7103177
...

Sheet City ​​of Valencia
B2: Company | C2: Type | D2: Infrastructure | E2: Type Infrastructure | F2: City | G2: Zip Code | H2: Location | I2: Address | J2: Latitude | K2: Longitude
B4: InPost | C4: Convenience stores | D4: Private | E4: Premises | F4: Valencia | G4: 46001 | H4: Perfumarte Maria Cristina | I4: C. de María Cristina, 9 | J4: 39,47310955975495 | K4: -0.377633211837713
B5: InPost | C5: Lockers | D5: Private | E5: Premises | F5: Valencia | G5: 46003 | H5: Carmen Laundry | I5: C. de Alejandra Soler, 9 | J5: 39,47756090944269 | K5: -0.3828099665562772
B6: InPost | C6: Convenience stores | D6: Private | E6: Premises | F6: Valencia | G6: 46001 | H6: Valira Tienda De Fabrica | I6: Calle del Músico Peydró, 30 | J6: 39.47179659723847 | K6: -0.37849382111226193
B7: InPost | C7: Convenience stores | D7: Private | E7: Premises | F7: Valencia | G7: 46003 | H7: Economy Print | I7: C/ de Ripalda, 20 | J7: 39.47889580112418 | K7: -0.38124623090782084
B8: InPost | C8: Lockers | D8: Private | E8: Premises | F8: Valencia | G8: 46008 | H8: Carmen Laundry 2 | I8: C. de Quart, 125 | J8: 39.47473011396571 | K8: -0.3901642470217949
B9: InPost | C9: Lockers | D9: Private | E9: Supermarket | F9: Valencia | G9: 46008 | H9: Dia C/ Juan Llorens | I9: C. de Juan Llorens, 10 | J9: 39.47356343765982 | K9: -0.3913135158114307
B10: InPost | C10: Lockers | D10: Private | E10: Supermarket | F10: Valencia | G10: 46003 | H10: Superm Charter C/Salvado | I10: C/ de Salvador Giner, 22 | J10: 39.48075067455666 | K10: -0.3798377191040145
B11: InPost | C11: Convenience stores | D11: Private | E11: Kiosk | F11: Valencia | G11: 46008 | H11: El Quiosc | I11: C. de San Ignacio de Loyola | J11: 39.47389899460428 | K11: -0.3896573891830816
B12: InPost | C12: Convenience stores | D12: Private | E12: Premises | F12: Valencia | G12: 46008 | H12: Expendeduria 156 | I12: C. de Calixto III, 1 | J12: 39.47253854767568 | K12: -0.3867316660609
B13: InPost | C13: Convenience stores | D13: Private | E13: Premises | F13: Valencia | G13: 46008 | H13: Kalinopa | I13: Gran Vía de Fernando el Católico, 56 | J13: 39.473999706363465 | K13: -0.3868670342211692
B14: InPost | C14: Convenience stores | D14: Private | E14: Premises | F14: Valencia | G14: 46008 | H14: Outlet Destino 8 | I14: C/ Angel Guimera, 30 | J14: 39.470344474685916 | K14: -0.38684924402987636
B15: InPost | C15: Lockers | D15: Private | E15: Premises | F15: Valencia | G15: 46003 | H15: Lacolada Ciutat Vella | I15: C. de la Blanqueria, 9 | J15: 39.48015886194766 | K15: -0.377359092388655
... B98: InPost | C98: Convenience stores | D98: Private | E98: Premises | F98: Valencia | G98: 46004 | H98: Locutorio Paris | I98: C. de Luis Oliag, 40 | J98: 39.46101263079718 | K98: -0.36480913017180744
B99: InPost | C99: Lockers | D99: Private | E99: Parking | F99: Valencia | G99: 46021 | H99: 24/7 Parking Apk2 Aragon | I99: Carrer de Xile, s/n | J99: 39.47178653962879 | K99: -0.35637027
B100: InPost | C100: Lockers | D100: Private | E100: Premises | F100: Valencia | G100: 46010 | H100: Blue Onyx Lavanderia | I100: C. de Menéndez y Pelayo, 24 | J100: 39.47846682104921 | K100: -0.3554090241374535
B101: InPost | C101: Convenience stores | D101: Private | E101: Premises | F101: Valencia | G101: 46004 | H101: Js Moviles | I101: Av. Dr. Waksman, 25 | J101: 39.45662198521995 | K101: -0.37259195129060435
B102: Correos | C102: Lockers | D102: Public | E102: Public facility | F102: Valencia | G102: 46009 | H102: Correos Valencia Suc 5. La SaãDia | I102: Av. de la Constitución, 111 | J102: 39.49035630671944 | K102: -0.375452129865151
B103: Correos | C103: Lockers | D103: Private | E103: Supermarket | F103: Valencia | G103: 46008 | H103: Supermercados Consum | I103: C/ Angel Guimera, 70 | J103: 39.46979785891765 | K103: -0.39097114116827675
B104: Correos | C104: Lockers | D104: Private | E104: Supermarket | F104: Valencia | G104: 46021 | H104: Supermercados Consum | I104: Av. del Puerto, 79 | J104: 39.466254800295886 | K104: -0.35248173362930457
B105: Correos | C105: Lockers | D105: Private | E105: Supermarket | F105: Valencia | G105: 46006 | H105: Supermercados Consum | I105: C. de Sueca, 34 | J105: 39.46141306231918 | K105: -0.3750785067165566
B106: Correos | C106: Lockers | D106: Private | E106: Supermarket | F106: Valencia | G106: 46010 | H106: Supermercados Consum | I106: C. Alboraya, 31 | J106: 39.48285278565497 | K106: -0.3704926740639288
B107: Correos | C107: LSP PUDOs | D107: Public | E107: Public facility | F107: Valencia | G107: 46021 | H107: Correos Valencia Suc 13. Algirã’s | I107: C. del Poeta Mas y Ros, 20 | J107: 39.47105061897009 | K107: -0.3497979010943048
B108: Correos | C108: LSP PUDOs | D108: Public | E108: Public facility | F108: Valencia | G108: 46011 | H108: Correos Valencia Suc 6. Puerto | I108: C. Dr. Juan José Dómine, 13 | J108: 39.46221975511138 | K108: -0.3314543872585992
B109: Correos | C109: Lockers | D109: Public | E109: Public facility | F109: Valencia | G109: 46021 | H109: Correos Valencia Suc 13. Algirã’s | I109: C. del Poeta Mas y Ros, 20 | J109: 39.47105061897009 | K109: -0.3497979010943048
B110: Correos | C110: Lockers | D110: Public | E110: Public facility | F110: Valencia | G110: 46011 | H110: Correos Valencia Suc 6. Puerto | I110: C. Dr. Juan José Dómine, 13 | J110: 39.46221975511138 | K110: -0.3314543872585992
B111: Correos | C111: Lockers | D111: Public | E111: Public Infrastructure | F111: Valencia | G111: 46004 | H111: Estacion De Metro Xativa | I111: C. Xátiva, s/n | J111: 39.46761031087426 | K111: -0.3768970377143659
... B150: Amazon | C150: Convenience stores | D150: Private | E150: Premises | F150: Valencia | G150: 46005 | H150: Estanco Joaquin Costa 44 | I150: C. Joaquín Costa, 44 | J150: 39.46457344018159 | K150: -0.36625796047850223
B151: Amazon | C151: Convenience stores | D151: Private | E151: Premises | F151: Valencia | G151: 46005 | H151: Nickname Store | I151: C. de Joaquín Costa, 37 | J151: 40.44461476129101 | K151: -0.36844483
B152: Amazon | C152: Lockers | D152: Public | E152: Public facility | F152: Valencia | G152: 46005 | H152: Citypaq Lockerss-Correos València Suc 9. Joaquin Co | I152: C. de Joaquín Costa, 39 | J152: 40.44436179791772 | K152: -0.36839315
B153: Amazon | C153: Convenience stores | D153: Public | E153: Public facility | F153: Valencia | G153: 46005 | H153: Correos - València Suc 9. Joaquin Costa | I153: C. de Joaquín Costa, 39 | J153: 40.44436179791772 | K153: -0.36839315
B154: Amazon | C154: Convenience stores | D154: Private | E154: Kiosk | F154: Valencia | G154: 46005 | H154: Kiosko Angeles | I154: C. del Pintor Salvador Abril, 18 | J154: 39.463754935917095 | K154: -0.3707043261626431
B155: Amazon | C155: Convenience stores | D155: Private | E155: Premises | F155: Valencia | G155: 46005 | H155: Seur - Karpet Papeleria Tecnica | I155: C. Joaquín Costa, 46 | J155: 39.46445347966288 | K155: -0.36608867443925336
B156: Amazon | C156: Convenience stores | D156: Private | E156: Premises | F156: Valencia | G156: 46005 | H156: Seur - Texto Graf | I156: Calle de Matías Perelló, 27 | J156: 39.461753537073136 | K156: -0.3676080029272786
B157: Amazon | C157: Convenience stores | D157: Private | E157: Premises | F157: Valencia | G157: 46005 | H157: Libreria Salamanca | I157: C. de Salamanca, 42 | J157: 39.465088498072824 | K157: -0.3634071446984216
B158: Amazon | C158: Convenience stores | D158: Private | E158: Premises | F158: Valencia | G158: 46005 | H158: Papelería Barco De Papel | I158: C. de Salamanca, 47 | J158: 39.46475085560623 | K158: -0.36267141867309804
B159: Amazon | C159: Convenience stores | D159: Private | E159: Premises | F159: Valencia | G159: 46006 | H159: Estanco Garna | I159: C. de Luis Oliag, 25 | J159: 39.45959149555638 | K159: -0.36684328045319314
B160: Amazon | C160: Convenience stores | D160: Private | E160: Premises | F160: Valencia | G160: 46006 | H160: Seur - Estanco Garna Valencia 13 | I160: C. de Luis Oliag, 25 | J160: 39.45959149555638 | K160: -0.36684328045319314
B161: Amazon | C161: Convenience stores | D161: Private | E161: Premises | F161: Valencia | G161: 46006 | H161: 1x2 Mercat Russafa | I161: C. del Consulat del Mar, 5 | J161: 39.463014162723226 | K161: -0.37127278020055776
B162: Amazon | C162: Convenience stores | D162: Private | E162: Premises | F162: Valencia | G162: 46006 | H162: Seur - Ibertinta Valencia | I162: PERIS Y VALERO 85 | J162: 39.45908593409706 | K162: -0.37195494772591703
...

Sheet Sheet3
A1: Company | B1: Type | C1: Infrastructure | D1: Type Infrastructure | E1: City | F1: Zip Code | G1: Location | H1: Address | I1: Latitude | J1: Longitude | M1: Type | N1: Count of Company
A2: InPost | B2: Convenience stores | C2: Private | D2: Premises | E2: Valencia | F2: 46001 | G2: Perfumarte Maria Cristina | H2: C. de María Cristina, 9 | I2: 39,47310955975495 | J2: -0.377633211837713 | M2: Click&Collect | N2: 24
A3: InPost | B3: Lockers | C3: Private | D3: Premises | E3: Valencia | F3: 46003 | G3: Carmen Laundry | H3: C. de Alejandra Soler, 9 | I3: 39,47756090944269 | J3: -0.3828099665562772 | M3: Convenience stores | N3: 768
A4: InPost | B4: Convenience stores | C4: Private | D4: Premises | E4: Valencia | F4: 46001 | G4: Valira Tienda De Fabrica | H4: Calle del Músico Peydró, 30 | I4: 39.47179659723847 | J4: -0.37849382111226193 | M4: Lockers | N4: 126
A5: InPost | B5: Convenience stores | C5: Private | D5: Premises | E5: Valencia | F5: 46003 | G5: Economy Print | H5: C/ de Ripalda, 20 | I5: 39.47889580112418 | J5: -0.38124623090782084 | M5: LSP PUDOs | N5: 48
A6: InPost | B6: Lockers | C6: Private | D6: Premises | E6: Valencia | F6: 46008 | G6: Carmen Laundry 2 | H6: C. de Quart, 125 | I6: 39.47473011396571 | J6: -0.3901642470217949 | M6: Total general | N6: 966
A7: InPost | B7: Lockers | C7: Private | D7: Supermarket | E7: Valencia | F7: 46008 | G7: Dia C/ Juan Llorens | H7: C. de Juan Llorens, 10 | I7: 39.47356343765982 | J7: -0.3913135158114307
A8: InPost | B8: Lockers | C8: Private | D8: Supermarket | E8: Valencia | F8: 46003 | G8: Superm Charter C/Salvado | H8: C/ de Salvador Giner, 22 | I8: 39.48075067455666 | J8: -0.3798377191040145
A9: InPost | B9: Convenience stores | C9: Private | D9: Kiosk | E9: Valencia | F9: 46008 | G9: El Quiosc | H9: C. de San Ignacio de Loyola | I9: 39.47389899460428 | J9: -0.3896573891830816
A10: InPost | B10: Convenience stores | C10: Private | D10: Premises | E10: Valencia | F10: 46008 | G10: Expendeduria 156 | H10: C. de Calixto III, 1 | I10: 39.47253854767568 | J10: -0.3867316660609
A11: InPost | B11: Convenience stores | C11: Private | D11: Premises | E11: Valencia | F11: 46008 | G11: Kalinopa | H11: Gran Vía de Fernando el Católico, 56 | I11: 39.473999706363465 | J11: -0.3868670342211692
A12: InPost | B12: Convenience stores | C12: Private | D12: Premises | E12: Valencia | F12: 46008 | G12: Outlet Destino 8 | H12: C/ Angel Guimera, 30 | I12: 39.470344474685916 | J12: -0.38684924402987636
A13: InPost | B13: Lockers | C13: Private | D13: Premises | E13: Valencia | F13: 46003 | G13: Lacolada Ciutat Vella | H13: C. de la Blanqueria, 9 | I13: 39.48015886194766 | J13: -0.377359092388655
A14: InPost | B14: Convenience stores | C14: Private | D14: Premises | E14: Valencia | F14: 46008 | G14: Milar Gran Via | H14: Gran Vía de Fernando el Católico, 3 | I14: 39.46946482690077 | J14: -0.3846478777238517
A15: InPost | B15: Convenience stores | C15: Private | D15: Premises | E15: Valencia | F15: 46003 | G15: Naturalworld | H15: Carrer de Roteros, 2 | I15: 39.47915825477076 | J15: -0.37623654083541874
A16: InPost | B16: Convenience stores | C16: Private | D16: Premises | E16: Valencia | F16: 46008 | G16: Plantas Y Flores Lantana | H16: Calle de Sta. María Micaela | I16: 39.47227140704873 | J16: -0.39205425075201217
A17: InPost | B17: Convenience stores | C17: Private | D17: Premises | E17: Valencia | F17: 46009 | G17: El Trebol Del Turia | H17: Av. de Burjassot, 18 | I17: 39.484222876226845 | J17: -0.38252617528850646
A18: InPost | B18: Convenience stores | C18: Private | D18: Premises | E18: Valencia | F18: 46008 | G18: Firdos Movil | H18: C. de Martín el Humano, 30 | I18: 39.46981902183968 | J18: -0.3902598607606746
... A95: InPost | B95: Convenience stores | C95: Private | D95: Premises | E95: Valencia | F95: 46004 | G95: Locutorio Paris | H95: C. de Luis Oliag, 40 | I95: 39.46101263079718 | J95: -0.36480913017180744
A96: InPost | B96: Lockers | C96: Private | D96: Parking | E96: Valencia | F96: 46021 | G96: 24/7 Parking Apk2 Aragon | H96: Carrer de Xile, s/n | I96: 39.47178653962879 | J96: -0.35637027
A97: InPost | B97: Lockers | C97: Private | D97: Premises | E97: Valencia | F97: 46010 | G97: Blue Onyx Lavanderia | H97: C. de Menéndez y Pelayo, 24 | I97: 39.47846682104921 | J97: -0.3554090241374535
A98: InPost | B98: Convenience stores | C98: Private | D98: Premises | E98: Valencia | F98: 46004 | G98: Js Moviles | H98: Av. Dr. Waksman, 25 | I98: 39.45662198521995 | J98: -0.37259195129060435
A99: Correos | B99: Lockers | C99: Public | D99: Public facility | E99: Valencia | F99: 46009 | G99: Correos Valencia Suc 5. La SaãDia | H99: Av. de la Constitución, 111 | I99: 39.49035630671944 | J99: -0.375452129865151
A100: Correos | B100: Lockers | C100: Private | D100: Supermarket | E100: Valencia | F100: 46008 | G100: Supermercados Consum | H100: C/ Angel Guimera, 70 | I100: 39.46979785891765 | J100: -0.39097114116827675
A101: Correos | B101: Lockers | C101: Private | D101: Supermarket | E101: Valencia | F101: 46021 | G101: Supermercados Consum | H101: Av. del Puerto, 79 | I101: 39.466254800295886 | J101: -0.35248173362930457
A102: Correos | B102: Lockers | C102: Private | D102: Supermarket | E102: Valencia | F102: 46006 | G102: Supermercados Consum | H102: C. de Sueca, 34 | I102: 39.46141306231918 | J102: -0.3750785067165566
A103: Correos | B103: Lockers | C103: Private | D103: Supermarket | E103: Valencia | F103: 46010 | G103: Supermercados Consum | H103: C. Alboraya, 31 | I103: 39.48285278565497 | J103: -0.3704926740639288
A104: Correos | B104: LSP PUDOs | C104: Public | D104: Public facility | E104: Valencia | F104: 46021 | G104: Correos Valencia Suc 13. Algirã’s | H104: C. del Poeta Mas y Ros, 20 | I104: 39.47105061897009 | J104: -0.3497979010943048
A105: Correos | B105: LSP PUDOs | C105: Public | D105: Public facility | E105: Valencia | F105: 46011 | G105: Correos Valencia Suc 6. Puerto | H105: C. Dr. Juan José Dómine, 13 | I105: 39.46221975511138 | J105: -0.3314543872585992
A106: Correos | B106: Lockers | C106: Public | D106: Public Infrastructure | E106: Valencia | F106: 46004 | G106: Estacion De Metro Xativa | H106: C. Xátiva, s/n | I106: 39.46761031087426 | J106: -0.3768970377143659
A107: Correos | B107: LSP PUDOs | C107: Public | D107: Public facility | E107: Valencia | F107: 46023 | G107: Correos Valencia Suc 22. El Corte Inglã‰S Av. Francia | H107: C/ del Pintor Maella, 37 | I107: 39.45707810033234 | J107: -0.34715042196515755
A108: Correos | B108: LSP PUDOs | C108: Public | D108: Public facility | E108: Valencia | F108: 46015 | G108: Correos Valencia Suc 10. Benicalap | H108: Av. del General Avilés, 8 | I108: 39.48837160586209 | J108: -0.3913537116204853
... A142: Amazon | B142: Convenience stores | C142: Private | D142: Premises | E142: Valencia | F142: 46005 | G142: Estanco Joaquin Costa 44 | H142: C. Joaquín Costa, 44 | I142: 39.46457344018159 | J142: -0.36625796047850223
A143: Amazon | B143: Convenience stores | C143: Private | D143: Premises | E143: Valencia | F143: 46005 | G143: Nickname Store | H143: C. de Joaquín Costa, 37 | I143: 40.44461476129101 | J143: -0.36844483
A144: Amazon | B144: Lockers | C144: Public | D144: Public facility | E144: Valencia | F144: 46005 | G144: Citypaq Lockerss-Correos València Suc 9. Joaquin Co | H144: C. de Joaquín Costa, 39 | I144: 40.44436179791772 | J144: -0.36839315
A145: Amazon | B145: Convenience stores | C145: Private | D145: Kiosk | E145: Valencia | F145: 46005 | G145: Kiosko Angeles | H145: C. del Pintor Salvador Abril, 18 | I145: 39.463754935917095 | J145: -0.3707043261626431
A146: Amazon | B146: Convenience stores | C146: Private | D146: Premises | E146: Valencia | F146: 46005 | G146: Seur - Karpet Papeleria Tecnica | H146: C. Joaquín Costa, 46 | I146: 39.46445347966288 | J146: -0.36608867443925336
A147: Amazon | B147: Convenience stores | C147: Private | D147: Premises | E147: Valencia | F147: 46005 | G147: Seur - Texto Graf | H147: Calle de Matías Perelló, 27 | I147: 39.461753537073136 | J147: -0.3676080029272786
A148: Amazon | B148: Convenience stores | C148: Private | D148: Premises | E148: Valencia | F148: 46005 | G148: Libreria Salamanca | H148: C. de Salamanca, 42 | I148: 39.465088498072824 | J148: -0.3634071446984216
A149: Amazon | B149: Convenience stores | C149: Private | D149: Premises | E149: Valencia | F149: 46005 | G149: Papelería Barco De Papel | H149: C. de Salamanca, 47 | I149: 39.46475085560623 | J149: -0.36267141867309804
...

Sheet City ​​of Barcelona
B2: Company | C2: Type | D2: Infrastructure | E2: Type Infrastructure | F2: City | G2: Zip Code | H2: Location | I2: Address | J2: Latitude | K2: Longitude
B4: InPost | C4: Convenience stores | D4: Private | E4: Premises | F4: Barcelona | G4: 8001 | H4: Mobil Mania | I4: Rambla del Raval, 6 | J4: 41.379004 | K4: 2.1686181
B5: InPost | C5: Convenience stores | D5: Private | E5: Premises | F5: Barcelona | G5: 8001 | H5: Impremta Sebtor | I5: Carrer de l'Hospital, 157 | J5: 41.379647 | K5: 2.1664182
B6: InPost | C6: Lockers | D6: Private | E6: Parking | F6: Barcelona | G6: 8001 | H6: Lockers 24/7 Saba Illa Raval Bar | I6: C. de San Rafael, 15 | J6: 41.379093 | K6: 2.170133
B7: InPost | C7: Convenience stores | D7: Private | E7: Premises | F7: Barcelona | G7: 8001 | H7: Copisteria Geografia Ub | I7: Carrer de les Ramelleres, 21 | J7: 41.384566 | K7: 2.1683374
B8: InPost | C8: Convenience stores | D8: Private | E8: Premises | F8: Barcelona | G8: 8001 | H8: Copywork | I8: C. de Joaquín Costa, 2 | J8: 41.381177 | K8: 2.1675444
B9: InPost | C9: Convenience stores | D9: Private | E9: Premises | F9: Barcelona | G9: 8001 | H9: Madiha Fashion | I9: Carrer Nou de la Rambla, 22 | J9: 41.378721 | K9: 2.1734232
B10: InPost | C10: Convenience stores | D10: Private | E10: Kiosk | F10: Barcelona | G10: 8001 | H10: Kiosco De Prensa | I10: Rda. de Sant Antoni, 100 | J10: 41.385135 | K10: 2.164182
B11: InPost | C11: Convenience stores | D11: Private | E11: Premises | F11: Barcelona | G11: 8001 | H11: Copypelai | I11: Carrer de Pelai, 9 | J11: 41.386088 | K11: 2.1665315
B12: InPost | C12: Convenience stores | D12: Private | E12: Premises | F12: Barcelona | G12: 8001 | H12: Phonix The Smart Point | I12: Carrer de Jovellanos, 1 | J12: 41.385091 | K12: 2.1678865
B13: InPost | C13: Convenience stores | D13: Private | E13: Premises | F13: Barcelona | G13: 8001 | H13: Fiber Sonic | I13: Carrer del Tigre, 33 | J13: 41.382352 | K13: 2.1638637
B14: InPost | C14: Convenience stores | D14: Private | E14: Premises | F14: Barcelona | G14: 8002 | H14: Taha Mobile Shop | I14: Carrer d'Avinyó, 29 | J14: 41.380705 | K14: 2.1784414
B15: InPost | C15: Convenience stores | D15: Private | E15: Premises | F15: Barcelona | G15: 8002 | H15: Te Habla Mobile Mobile | I15: Carrer de Josep Anselm Clavé, 27 | J15: 41.378192 | K15: 2.1780974
... B2295: Amazon | C2295: Estación logistica de ultima milla | D2295: Private | E2295: industrial estate | F2295: Barcelona | G2295: 8210 | H2295: DCT4 Amazon - Última milla / Amazon Logistics Station | I2295: Av. de Can Rosés, 9 Rubí | J2295: 41.505545 | K2295: 2.041015
B2296: Amazon | C2296: Centros de distribución/recepción | D2296: Private | E2296: industrial estate | F2296: Barcelona | G2296: 8100 | I2296: Carrer de Facundo Bacardí, 10, Mollet del Vallès | J2296: 41.551732 | K2296: 2.2301543
B2297: Amazon | C2297: Estación logistica de ultima milla | D2297: Private | E2297: industrial estate | F2297: Barcelona | G2297: 8110 | I2297: Carrer Fresser, Montcada i Reixac | J2297: 41.501999 | K2297: 2.1897093
B2298: Correos | C2298: Estación logistica de ultima milla | D2298: Public | E2298: Industrial estate | F2298: Barcelona | G2298: 8174 | H2298: (CTA) Centro de distribución urbana o estación de última milla | I2298: Carrer del Danubi, 12, Sant Cugat del Vallès | J2298: 41.487303 | K2298: 2.0496882
B2299: Correos | C2299: Estación logistica de ultima milla | D2299: Public | E2299: Industrial estate | F2299: Barcelona | G2299: 8040 | H2299: (CTA) Centro de distribución urbana o estación de última milla | I2299: Carrer Número 29, 12, Sants-Montjuïc | J2299: 41.33884 | K2299: 2.1276809
B2300: Correos | C2300: Estación logistica de ultima milla | D2300: Public | E2300: Industrial estate | F2300: Barcelona | G2300: 8038 | I2300: Passeig Josep Carner, 33, Sants-Montjuïc | J2300: 41.372343 | K2300: 2.1755215
B2301: Correos | C2301: Centros de distribución/recepción | D2301: Public | E2301: Industrial estate | F2301: Barcelona | G2301: 8820 | I2301: Carrer de Estel Polar, 5, El Prat de Llobregat | J2301: 41.299485 | K2301: 2.064535
B2302: Correos Express | C2302: Estación logistica de ultima milla | D2302: Public | E2302: Industrial estate | F2302: Barcelona | G2302: 8830 | H2302: Centro de distribución urbana o estación de última milla | I2302: Carrer dels Filats, Nave 4, 08830 Sant Boi de Llobregat | J2302: 41.325119 | K2302: 2.0421193
B2303: Correos Express | C2303: Centros de distribución/recepción | D2303: Public | E2303: Industrial estate | F2303: Barcelona | G2303: 8130 | H2303: Plataformas de consolidación y reparto provincial. | I2303: Carrer de Can Banús, S/N, Santa Perpètua de Mogoda | J2303: 41.537805 | K2303: 2.1868651
B2304: Mondial Relay (Impost) | C2304: Estación logistica de ultima milla | D2304: Private | E2304: Industrial estate | F2304: Barcelona | G2304: 8800 | H2304: Centro de distribución urbana o estación de última milla | I2304: Carrer de les Oliveres, 1, 08800 Vilanova i la Geltrú | J2304: 41.245688 | K2304: 1.7237655
B2305: Seur | C2305: Centros de distribución/recepción | D2305: Private | E2305: Industrial estate | F2305: Barcelona | G2305: 8820 | H2305: Almacenamiento y cross-docking | I2305: Carrer Cal Nyepa, 23-27, 08820, Barcelona | J2305: 41.316114 | K2305: 2.1410141
B2306: Seur | C2306: Estación logistica de ultima milla | D2306: Private | E2306: Industrial estate | F2306: Barcelona | G2306: 8821 | H2306: Centro de distribución urbana o estación de última milla | I2306: Carrer Cal Fernando, 25, 08820 El Prat de Llobregat, Barcelona | J2306: 41.316196 | K2306: 2.140989
B2307: Seur | C2307: Centros de distribución/recepción | D2307: Private | E2307: Industrial estate | F2307: Barcelona | G2307: 8243 | I2307: Carrer de Ramon Farguell, 62, 08243 Manresa, Barcelona | J2307: 41.709494 | K2307: 1.8517822
B2308: Seur | C2308: Centros de distribución/recepción | D2308: Private | E2308: Industrial estate | F2308: Barcelona | G2308: 8210 | I2308: Poligono Industrial Can Salvatella, Av. Torre de Mateu, 93, 08210 Barberà del Vallès, Barcelona | J2308: 41.512914 | K2308: 2.1562297
B2309: DHL | C2309: Centros de distribución/recepción | D2309: Private | E2309: Industrial estate | F2309: Barcelona | G2309: 8820 | H2309: Almacenamiento y cross-docking | I2309: C/ L'Estany de la Messeguera, 14-24, El Prat de Llobregat | J2309: 41.319881 | K2309: 2.1359299
B2310: DHL | C2310: Centros de distribución/recepción | D2310: Private | E2310: Industrial estate | F2310: Barcelona | G2310: 8170 | H2310: Almacenamiento y cross-docking (Grandes Clientes) | I2310: Carrer d'Edison, 2, 08170 Montornès del Vallès | J2310: 41.557648 | K2310: 2.2609325
B2311: DHL | C2311: Estación logistica de ultima milla | D2311: Private | E2311: Industrial estate | F2311: Barcelona | G2311: 8130 | H2311: Centro de distribución urbana o estación de última milla | I2311: CIM del Valles, Santa Perpètua de Mogoda | J2311: 41.539973 | K2311: 2.1839371
B2312: DHL | C2312: Estación logistica de ultima milla | D2312: Private | E2312: Industrial estate | F2312: Tarragona | G2312: 43120 | H2312: Centro de distribución urbana o estación de última milla | I2312: Avinguda de les Puntes, Illa 6, Constantí, Tarragona | J2312: 41.164565 | K2312: 1.1590294
B2313: DHL | C2313: Centros de distribución/recepción | D2313: Private | E2313: Industrial estate | F2313: Barcelona | G2313: 8755 | I2313: Carrer Manganès, 3, Castellbisbal | J2313: 41.468075 | K2313: 1.952375
B2314: DHL | C2314: Centros de distribución/recepción | D2314: Private | E2314: Industrial estate | F2314: Barcelona | G2314: 8820 | I2314: C. Cal Truco, 50-60, 08820 El Prat de Llobregat | J2314: 41.314789 | K2314: 2.1410618
B2315: DHL | C2315: Centros de distribución/recepción | D2315: Private | E2315: Industrial estate | F2315: Barcelona | G2315: 8040 | I2315: Carrer de l'Atlàntic, 109, Sants-Montjuïc | J2315: 41.326815 | K2315: 2.1420242
B2316: DHL Express | C2316: Centros de distribución/recepción | D2316: Private | E2316: Industrial estate | F2316: Barcelona | G2316: 8820 | H2316: Consolidación internacional de exportaciones e importaciones | I2316: Aeropuerto de El Prat, Carrer de Estel Polar, 9332 | J2316: 41.298654 | K2316: 2.0635465
B2317: Fedex | C2317: Estación logistica de ultima milla | D2317: Private | E2317: Industrial estate | F2317: Barcelona | G2317: 8040 | H2317: Centro de distribución urbana o estación de última milla | I2317: Carrer Número 21, Sants-Montjuïc | J2317: 41.340491 | K2317: 2.1428507
B2318: Fedex | C2318: Centros de distribución/recepción | D2318: Private | E2318: Industrial estate | F2318: Barcelona | G2318: 8820 | H2318: Recogida y agrupacion de paquetes (tráfico aéreo o intermodal) | I2318: Carrer de Estel Polar, S/N | J2318: 41.297898 | K2318: 2.0602266
B2319: Celeritas | C2319: Centros de distribución/recepción | D2319: Private | E2319: Industrial estate | F2319: Barcelona | G2319: 8040 | H2319: Opera mediante almacenes de terceros en Barcelona | I2319: Sector C, Calle K (Zona Franca) | J2319: 41.327963 | K2319: 2.1134741
B2320: GLS | C2320: Centros de distribución/recepción | D2320: Private | E2320: Industrial estate | F2320: Barcelona | G2320: 8349 | H2320: Centro de distribución regional para reparto comarcal | I2320: Rda. Narcís Monturiol, 23-B, Cabrera de Mar | J2320: 41.529767 | K2320: 2.4147957
B2321: GLS | C2321: Centros de distribución/recepción | D2321: Private | E2321: Industrial estate | F2321: Barcelona | G2321: 8302 | H2321: Centro de distribución urbana o estación de última milla | I2321: Carrer de la Repuntadora, 45, Mataró | J2321: 41.528192 | K2321: 2.4269597
...

Sheet Sheet2
A1: Company | B1: Type | C1: Infrastructure | D1: Type Infrastructure | E1: City | F1: Zip Code | G1: Location | H1: Address | I1: Latitude | J1: Longitude | L1: Type | M1: Count of Company
A2: InPost | B2: Convenience stores | C2: Private | D2: Premises | E2: Barcelona | F2: 8001 | G2: Mobil Mania | H2: Rambla del Raval, 6 | I2: 41.379004 | J2: 2.1686181 | L2: Click&Collect | M2: 97
A3: InPost | B3: Convenience stores | C3: Private | D3: Premises | E3: Barcelona | F3: 8001 | G3: Impremta Sebtor | H3: Carrer de l'Hospital, 157 | I3: 41.379647 | J3: 2.1664182 | L3: Convenience stores | M3: 1541
A4: InPost | B4: Lockers | C4: Private | D4: Parking | E4: Barcelona | F4: 8001 | G4: Lockers 24/7 Saba Illa Raval Bar | H4: C. de San Rafael, 15 | I4: 41.379093 | J4: 2.170133 | L4: Lockers | M4: 504
A5: InPost | B5: Convenience stores | C5: Private | D5: Premises | E5: Barcelona | F5: 8001 | G5: Copisteria Geografia Ub | H5: Carrer de les Ramelleres, 21 | I5: 41.384566 | J5: 2.1683374 | L5: LSP PUDOs | M5: 109
A6: InPost | B6: Convenience stores | C6: Private | D6: Premises | E6: Barcelona | F6: 8001 | G6: Copywork | H6: C. de Joaquín Costa, 2 | I6: 41.381177 | J6: 2.1675444 | L6: Total general | M6: 2251
A7: InPost | B7: Convenience stores | C7: Private | D7: Premises | E7: Barcelona | F7: 8001 | G7: Madiha Fashion | H7: Carrer Nou de la Rambla, 22 | I7: 41.378721 | J7: 2.1734232
A8: InPost | B8: Convenience stores | C8: Private | D8: Kiosk | E8: Barcelona | F8: 8001 | G8: Kiosco De Prensa | H8: Rda. de Sant Antoni, 100 | I8: 41.385135 | J8: 2.164182
A9: InPost | B9: Convenience stores | C9: Private | D9: Premises | E9: Barcelona | F9: 8001 | G9: Copypelai | H9: Carrer de Pelai, 9 | I9: 41.386088 | J9: 2.1665315
A10: InPost | B10: Convenience stores | C10: Private | D10: Premises | E10: Barcelona | F10: 8001 | G10: Phonix The Smart Point | H10: Carrer de Jovellanos, 1 | I10: 41.385091 | J10: 2.1678865
A11: InPost | B11: Convenience stores | C11: Private | D11: Premises | E11: Barcelona | F11: 8001 | G11: Fiber Sonic | H11: Carrer del Tigre, 33 | I11: 41.382352 | J11: 2.1638637
A12: InPost | B12: Convenience stores | C12: Private | D12: Premises | E12: Barcelona | F12: 8002 | G12: Taha Mobile Shop | H12: Carrer d'Avinyó, 29 | I12: 41.380705 | J12: 2.1784414
A13: InPost | B13: Convenience stores | C13: Private | D13: Premises | E13: Barcelona | F13: 8002 | G13: Te Habla Mobile Mobile | H13: Carrer de Josep Anselm Clavé, 27 | I13: 41.378192 | J13: 2.1780974
A14: InPost | B14: Convenience stores | C14: Private | D14: Premises | E14: Barcelona | F14: 8002 | G14: Libreria Balmes | H14: Carrer de Duran i Bas, 11 | I14: 41.385813 | J14: 2.1745732
A15: InPost | B15: Convenience stores | C15: Private | D15: Premises | E15: Barcelona | F15: 8003 | G15: Estanc Bcn 159 | H15: Placeta de Montcada, 6 | I15: 41.384551 | J15: 2.1819846
A16: InPost | B16: Lockers | C16: Private | D16: Parking | E16: Barcelona | F16: 8003 | G16: Lockers 24/7 Saba Barceloneta Ba | H16: Carrer del Baluard, 27S | I16: 41.380092 | J16: 2.1890562
A17: InPost | B17: Convenience stores | C17: Private | D17: Premises | E17: Barcelona | F17: 8003 | G17: Punto Y Coma | H17: Carrer De Pepe Rubianes 12 | I17: 41.378379 | J17: 2.1893178
A18: InPost | B18: Convenience stores | C18: Private | D18: Premises | E18: Barcelona | F18: 8003 | G18: Instalaciones De La Fuente | H18: Carrer de la Mediterrània, 4 | I18: 41.382051 | J18: 2.1889039
... A2252: MRW | B2252: LSP PUDOs | C2252: Private | D2252: Premises | E2252: Barcelona | F2252: 8020 | G2252: Oficina Mrw 00637 | H2252: Rambla De Prim, 246 | I2252: 41.425173 | J2252: 2.2017844

Sheet Datos
B2: Ciudad | C2: Nº puntos por tipo | H2: Infrastructure | K2: Type Infrastructure | T2: Total
C4: Convenience stores | D4: Lockers | E4: Click&Collect | F4: LSP PUDOs | H4: Public | I4: Private | K4: Supermarket | L4: Parking | M4: Premises | N4: Kiosk | O4: Service Station | P4: Public facility | Q4: Public Infrastructure | R4: Mall | S4: Gym | T4: =SUM(T6+T11+T16) -> 6545
B6: Madrid | C6: =COUNTIF('City ​​of Madrid'!C4:C3285,Datos!C4) -> 2216 | D6: =COUNTIF('City ​​of Madrid'!C4:C3285,Datos!D4) -> 719 | E6: =COUNTIF('City ​​of Madrid'!C4:C3285,Datos!E4) -> 146 | F6: =COUNTIF('City ​​of Madrid'!C4:C3285,Datos!F4) -> 200 | H6: =COUNTIF('City ​​of Madrid'!D4:D3285,Datos!H4) -> 219 | I6: =COUNTIF('City ​​of Madrid'!D4:D3285,Datos!I4) -> 3061 | K6: =COUNTIF('City ​​of Madrid'!$E$4:$E$3285,Datos!K4) -> 178 | L6: =COUNTIF('City ​​of Madrid'!$E$4:$E$3285,Datos!L4) -> 111 | M6: =COUNTIF('City ​​of Madrid'!$E$4:$E$3285,Datos!M4) -> 2576 | N6: =COUNTIF('City ​​of Madrid'!$E$4:$E$3285,Datos!N4) -> 64 | O6: =COUNTIF('City ​​of Madrid'!$E$4:$E$3285,Datos!O4) -> 84 | P6: =COUNTIF('City ​​of Madrid'!$E$4:$E$3285,Datos!P4) -> 178 | Q6: =COUNTIF('City ​​of Madrid'!$E$4:$E$3285,Datos!Q4) -> 14 | R6: =COUNTIF('City ​​of Madrid'!$E$4:$E$3285,Datos!R4) -> 64 | S6: =COUNTIF('City ​​of Madrid'!$E$4:$E$3285,Datos!S4) -> 4 | T6: =SUM(C6:F6) -> 3281
C8: =C6/T6 -> 0.67540384 | D8: =D6/T6 -> 0.21914051 | E8: =E6/T6 -> 0.044498628 | F8: =F6/T6 -> 0.060957025 | H8: =H6/T6 -> 0.066747943 | I8: =I6/$T$6 -> 0.93294727 | K8: =K6/$T$6 -> 0.054251753 | L8: =L6/$T$6 -> 0.033831149 | M8: =M6/$T$6 -> 0.78512649 | N8: =N6/$T$6 -> 0.019506248 | O8: =O6/$T$6 -> 0.025601951 | P8: =P6/$T$6 -> 0.054251753 | Q8: =Q6/$T$6 -> 0.0042669918 | R8: =R6/$T$6 -> 0.019506248 | S8: =S6/$T$6 -> 0.0012191405
B11: Valencia | C11: =COUNTIF('City ​​of Valencia'!C4:C985,Datos!C4) -> 777 | D11: =COUNTIF('City ​​of Valencia'!C4:C985,Datos!D4) -> 133 | E11: =COUNTIF('City ​​of Valencia'!C4:C985,Datos!E4) -> 24 | F11: =COUNTIF('City ​​of Valencia'!C4:C985,Datos!F4) -> 48 | H11: =COUNTIF('City ​​of Valencia'!D4:D985,Datos!H4) -> 43 | I11: =COUNTIF('City ​​of Valencia'!D4:D985,Datos!I4) -> 939 | K11: =COUNTIF('City ​​of Valencia'!$E$4:$E$985,Datos!K4) -> 45 | L11: =COUNTIF('City ​​of Valencia'!$E$4:$E$985,Datos!L4) -> 17 | M11: =COUNTIF('City ​​of Valencia'!$E$4:$E$985,Datos!M4) -> 745 | N11: =COUNTIF('City ​​of Valencia'!$E$4:$E$985,Datos!N4) -> 93 | O11: =COUNTIF('City ​​of Valencia'!$E$4:$E$985,Datos!O4) -> 26 | P11: =COUNTIF('City ​​of Valencia'!$E$4:$E$985,Datos!P4) -> 39 | Q11: =COUNTIF('City ​​of Valencia'!$E$4:$E$985,Datos!Q4) -> 4 | R11: =COUNTIF('City ​​of Valencia'!$E$4:$E$985,Datos!R4) -> 9 | S11: =COUNTIF('City ​​of Valencia'!$E$4:$E$985,Datos!S4) -> 3 | T11: =SUM(C11:F11) -> 982
C13: =C11/T11 -> 0.79124236 | D13: =D11/T11 -> 0.13543788 | E13: =E11/T11 -> 0.024439919 | F13: =F11/T11 -> 0.048879837 | H13: =H11/T11 -> 0.043788187 | I13: =I11/$T$11 -> 0.95621181 | K13: =K11/$T$11 -> 0.045824847 | L13: =L11/$T$11 -> 0.017311609 | M13: =M11/$T$11 -> 0.7586558 | N13: =N11/$T$11 -> 0.094704684 | O13: =O11/$T$11 -> 0.026476578 | P13: =P11/$T$11 -> 0.039714868 | Q13: =Q11/$T$11 -> 0.0040733198 | R13: =R11/$T$11 -> 0.0091649695 | S13: =S11/$T$11 -> 0.0030549898
B16: Barcelona | C16: =COUNTIF('City ​​of Barcelona'!C4:C2285,C4) -> 1549 | D16: =COUNTIF('City ​​of Barcelona'!C4:C2285,D4) -> 524 | E16: =COUNTIF('City ​​of Barcelona'!C4:C2285,E4) -> 97 | F16: =COUNTIF('City ​​of Barcelona'!C4:C2285,F4) -> 112 | H16: =COUNTIF('City ​​of Barcelona'!D4:D2285,H4) -> 118 | I16: =COUNTIF('City ​​of Barcelona'!D4:D2285,I4) -> 2164 | K16: =COUNTIF('City ​​of Barcelona'!$E$4:$E$2285,K4) -> 148 | L16: =COUNTIF('City ​​of Barcelona'!$E$4:$E$2285,L4) -> 217 | M16: =COUNTIF('City ​​of Barcelona'!$E$4:$E$2285,M4) -> 1652 | N16: =COUNTIF('City ​​of Barcelona'!$E$4:$E$2285,N4) -> 104 | O16: =COUNTIF('City ​​of Barcelona'!$E$4:$E$2285,O4) -> 46 | P16: =COUNTIF('City ​​of Barcelona'!$E$4:$E$2285,P4) -> 76 | Q16: =COUNTIF('City ​​of Barcelona'!$E$4:$E$2285,Q4) -> 20 | R16: =COUNTIF('City ​​of Barcelona'!$E$4:$E$2285,R4) -> 16 | S16: =COUNTIF('City ​​of Barcelona'!$E$4:$E$2285,S4) -> 1 | T16: =SUM(C16:F16) -> 2282
C18: =C16/T16 -> 0.67879053 | D18: =D16/T16 -> 0.22962314 | E18: =E16/T16 -> 0.042506573 | F18: =F16/T16 -> 0.049079755 | H18: =H16/T16 -> 0.051709027 | I18: =I16/$T$16 -> 0.94829097 | K18: =K16/$T$16 -> 0.06485539 | L18: =L16/$T$16 -> 0.095092025 | M18: =M16/$T$16 -> 0.72392638 | N18: =N16/$T$16 -> 0.045574058 | O18: =O16/$T$16 -> 0.020157756 | P18: =P16/$T$16 -> 0.033304119 | Q18: =Q16/$T$16 -> 0.0087642419 | R18: =R16/$T$16 -> 0.0070113935 | S18: =S16/$T$16 -> 0.00043821209
B23: Ciudad | C23: Nº Códigos Postales | D23: Nº Empresas | E23: Nº tipos de infraestructura
B25: Madrid | C25: {=SUM(1/COUNTIF('City ​​of Madrid'!G4:G3285,'City ​​of Madrid'!G4:G3285))} -> 75 | D25: {=SUM(1/COUNTIF('City ​​of Madrid'!B4:B3285,'City ​​of Madrid'!B4:B3285))} -> 13 | E25: {=SUM(1/COUNTIF('City ​​of Madrid'!E4:E3285,'City ​​of Madrid'!E4:E3285))} -> 11
B28: Valencia | C28: {=SUM(1/COUNTIF('City ​​of Valencia'!G4:G985,'City ​​of Valencia'!G4:G985))} -> 29 | D28: {=SUM(1/COUNTIF('City ​​of Valencia'!B4:B985,'City ​​of Valencia'!B4:B985))} -> 13 | E28: {=SUM(1/COUNTIF('City ​​of Valencia'!E4:E985,'City ​​of Valencia'!E4:E985))} -> 10
B31: Barcelona | C31: {=SUM(1/COUNTIF('City ​​of Barcelona'!G4:G2285,'City ​​of Barcelona'!G4:G2285))} -> 60 | D31: {=SUM(1/COUNTIF('City ​​of Barcelona'!B4:B2285,'City ​​of Barcelona'!B4:B2285))} -> 13 | E31: {=SUM(1/COUNTIF('City ​​of Barcelona'!E4:E2285,'City ​​of Barcelona'!E4:E2285))} -> 10
B37: Ciudad | C37: InPost | D37: Correos | E37: Amazon | F37: Seur | G37: DHL | H37: Celeritas | I37: CTT Express | J37: GLS | K37: Mail Boxes ETC | L37: Nacex | M37: UPS | N37: Drop Point Systems | O37: PUDO | P37: MRW | Q37: Totales
B39: Orden Empresa | C39: 2º | D39: 8º | E39: 1º | F39: 3º | G39: 7º | H39: 6º | I39: 4º | J39: 10º | K39: 12º | L39: 11º | M39: 5º | N39: 14º | O39: 9º | P39: 13º
C40: =C42/$Q$42 -> #REF! | D40: =D42/$Q$42 -> #REF! | E40: =E42/$Q$42 -> #REF! | F40: =F42/$Q$42 -> #REF! | G40: =G42/$Q$42 -> #REF! | H40: =H42/$Q$42 -> #REF! | I40: =I42/$Q$42 -> #REF! | J40: =J42/$Q$42 -> #REF! | ... P40: =P42/$Q$42 -> #REF! | Q40: =SUM(C40:P40) -> #REF!
B42: Total Puntos B2C Empresa | C42: =SUM(C75:C78) -> 1044 | D42: =SUM(D75:D78) -> 260 | E42: =SUM(E75:E78) -> 1092 | F42: =SUM(F75:F78) -> 1025 | G42: =SUM(G75:G78) -> 271 | H42: =SUM(H75:H78) -> 319 | I42: =SUM(I75:I78) -> 783 | J42: =SUM(J75:J78) -> 162 | ... P42: =SUM(P75:P78) -> 30 | Q42: =SUM(C42:P42) -> #REF!
B44: Madrid | U44: Media 3 ciudades
B46: Convenience stores | C46: =COUNTIF('City ​​of Madrid'!$C$4:$C$592,Datos!B46) -> 463 | D46: =COUNTIF('City ​​of Madrid'!$C$609:$C$770,Datos!B46) -> 0 | E46: =COUNTIF('City ​​of Madrid'!$C$772:$C$1323,Datos!B46) -> 304 | F46: =COUNTIF('City ​​of Madrid'!$C$1324:$C$1920,Datos!B46) -> 374 | G46: =COUNTIF('City ​​of Madrid'!$C$1927:$C$2045,Datos!B46) -> 111 | H46: =COUNTIF('City ​​of Madrid'!$C$2069:$C$2211,Datos!B46) -> 143 | I46: =COUNTIF('City ​​of Madrid'!$C$2227:$C$2621,Datos!B46) -> 395 | J46: =COUNTIF('City ​​of Madrid'!$C$2625:$C$2695,Datos!B46) -> 59 | K46: =COUNTIF('City ​​of Madrid'!$C$2764:$C$2773,Datos!B46) -> 0 | L46: =COUNTIF('City ​​of Madrid'!$C$2780:$C$2814,Datos!B46) -> 27 | M46: =COUNTIF('City ​​of Madrid'!$C$2923:$C$3100,Datos!B46) -> 148 | N46: =COUNTIF(#REF!,Datos!B46) -> #REF! | O46: =COUNTIF('City ​​of Madrid'!$C$3114:$C$3182,Datos!B46) -> 0 | P46: =COUNTIF('City ​​of Madrid'!$C$3260:$C$3267,Datos!B46) -> 0 | Q46: =SUM(C46:P46) -> #REF! | R46: 1º | S46: =Q46/$Q$51 -> #REF! | U46: Convenience stores | W46: =(S46+S55+S64)/3 -> #REF!
B47: Lockers | C47: =COUNTIF('City ​​of Madrid'!$C$4:$C$592,Datos!B47) -> 125 | D47: =COUNTIF('City ​​of Madrid'!$C$609:$C$770,Datos!B47) -> 73 | E47: =COUNTIF('City ​​of Madrid'!$C$772:$C$1323,Datos!B47) -> 248 | F47: =COUNTIF('City ​​of Madrid'!$C$1324:$C$1920,Datos!B47) -> 217 | G47: =COUNTIF('City ​​of Madrid'!$C$1927:$C$2045,Datos!B47) -> 0 | H47: =COUNTIF('City ​​of Madrid'!$C$2069:$C$2211,Datos!B47) -> 0 | I47: =COUNTIF('City ​​of Madrid'!$C$2227:$C$2621,Datos!B47) -> 0 | J47: =COUNTIF('City ​​of Madrid'!$C$2625:$C$2695,Datos!B47) -> 2 | K47: =COUNTIF('City ​​of Madrid'!$C$2764:$C$2773,Datos!B47) -> 0 | L47: =COUNTIF('City ​​of Madrid'!$C$2780:$C$2814,Datos!B47) -> 0 | M47: =COUNTIF('City ​​of Madrid'!$C$2923:$C$3100,Datos!B47) -> 30 | N47: =COUNTIF(#REF!,Datos!B47) -> #REF! | O47: =COUNTIF('City ​​of Madrid'!$C$3114:$C$3182,Datos!B47) -> 0 | P47: =COUNTIF('City ​​of Madrid'!$C$3260:$C$3267,Datos!B47) -> 0 | Q47: =SUM(C47:P47) -> #REF! | R47: 2º | S47: =Q47/$Q$51 -> #REF! | U47: Lockers | W47: =(S47+S56+S65)/3 -> #REF!
B48: Click&Collect | C48: =COUNTIF('City ​​of Madrid'!$C$4:$C$592,Datos!B48) -> 0 | D48: =COUNTIF('City ​​of Madrid'!$C$609:$C$770,Datos!B48) -> 0 | E48: =COUNTIF('City ​​of Madrid'!$C$772:$C$1323,Datos!B48) -> 0 | F48: =COUNTIF('City ​​of Madrid'!$C$1324:$C$1920,Datos!B48) -> 0 | G48: =COUNTIF('City ​​of Madrid'!$C$1927:$C$2045,Datos!B48) -> 0 | H48: =COUNTIF('City ​​of Madrid'!$C$2069:$C$2211,Datos!B48) -> 0 | I48: =COUNTIF('City ​​of Madrid'!$C$2227:$C$2621,Datos!B48) -> 0 | J48: =COUNTIF('City ​​of Madrid'!$C$2625:$C$2695,Datos!B48) -> 0 | K48: =COUNTIF('City ​​of Madrid'!$C$2764:$C$2773,Datos!B48) -> 0 | L48: =COUNTIF('City ​​of Madrid'!$C$2780:$C$2814,Datos!B48) -> 0 | M48: =COUNTIF('City ​​of Madrid'!$C$2923:$C$3100,Datos!B48) -> 0 | N48: =COUNTIF(#REF!,Datos!B48) -> #REF! | O48: =COUNTIF('City ​​of Madrid'!$C$3114:$C$3182,Datos!B48) -> 69 | P48: =COUNTIF('City ​​of Madrid'!$C$3260:$C$3267,Datos!B48) -> 0 | Q48: =SUM(C48:P48) -> #REF! | R48: 4º | S48: =Q48/$Q$51 -> #REF! | U48: Click&Collect | W48: =(S48+S57+S66)/3 -> #REF!
B49: LSP PUDOs | C49: =COUNTIF('City ​​of Madrid'!$C$4:$C$592,Datos!B49) -> 0 | D49: =COUNTIF('City ​​of Madrid'!$C$609:$C$770,Datos!B49) -> 89 | E49: =COUNTIF('City ​​of Madrid'!$C$772:$C$1323,Datos!B49) -> 0 | F49: =COUNTIF('City ​​of Madrid'!$C$1324:$C$1920,Datos!B49) -> 6 | G49: =COUNTIF('City ​​of Madrid'!$C$1927:$C$2045,Datos!B49) -> 8 | H49: =COUNTIF('City ​​of Madrid'!$C$2069:$C$2211,Datos!B49) -> 0 | I49: =COUNTIF('City ​​of Madrid'!$C$2227:$C$2621,Datos!B49) -> 0 | J49: =COUNTIF('City ​​of Madrid'!$C$2625:$C$2695,Datos!B49) -> 10 | K49: =COUNTIF('City ​​of Madrid'!$C$2764:$C$2773,Datos!B49) -> 10 | L49: =COUNTIF('City ​​of Madrid'!$C$2780:$C$2814,Datos!B49) -> 8 | M49: =COUNTIF('City ​​of Madrid'!$C$2923:$C$3100,Datos!B49) -> 0 | N49: =COUNTIF(#REF!,Datos!B49) -> #REF! | O49: =COUNTIF('City ​​of Madrid'!$C$3114:$C$3182,Datos!B49) -> 0 | P49: =COUNTIF('City ​​of Madrid'!$C$3260:$C$3267,Datos!B49) -> 8 | Q49: =SUM(C49:P49) -> #REF! | R49: 3º | S49: =Q49/$Q$51 -> #REF! | U49: LSP PUDOs | W49: =(S49+S58+S67)/3 -> #REF!
C51: =COUNTIF('City ​​of Madrid'!$B$4:B3267,Datos!C37) -> 589 | D51: =COUNTIF('City ​​of Madrid'!$B$4:B3267,Datos!D37) -> 178 | E51: =COUNTIF('City ​​of Madrid'!$B$4:B3267,Datos!E37) -> 553 | F51: =COUNTIF('City ​​of Madrid'!$B$4:B3267,Datos!F37) -> 597 | G51: =COUNTIF('City ​​of Madrid'!$B$4:B3267,Datos!G37) -> 125 | H51: =COUNTIF('City ​​of Madrid'!$B$4:B3267,Datos!H37) -> 181 | I51: =COUNTIF('City ​​of Madrid'!$B$4:B3267,Datos!I37) -> 398 | J51: =COUNTIF('City ​​of Madrid'!$B$4:B3267,Datos!J37) -> 139 | K51: =COUNTIF('City ​​of Madrid'!$B$4:B3267,Datos!K37) -> 16 | L51: =COUNTIF('City ​​of Madrid'!$B$4:B3267,Datos!L37) -> 93 | M51: =COUNTIF('City ​​of Madrid'!$B$4:B3267,Datos!M37) -> 241 | N51: =COUNTIF('City ​​of Madrid'!$B$4:B3267,Datos!N37) -> 0 | O51: =COUNTIF('City ​​of Madrid'!$B$4:B3267,Datos!O37) -> 146 | P51: =COUNTIF('City ​​of Madrid'!$B$4:B3267,Datos!P37) -> 8 | Q51: =SUM(C51:P51) -> 3264
B53: Valencia
B55: Convenience stores | C55: =COUNTIF('City ​​of Valencia'!$C$4:$C$101,Datos!B55) -> 81 | D55: =COUNTIF('City ​​of Valencia'!$C$102:$C$133,Datos!B55) -> 0 | E55: =COUNTIF('City ​​of Valencia'!$C$134:$C$349,Datos!B55) -> 157 | F55: =COUNTIF('City ​​of Valencia'!$C$350:$C$460,Datos!B55) -> 79 | G55: =COUNTIF('City ​​of Valencia'!$C$461:$C$517,Datos!B55) -> 53 | H55: =COUNTIF('City ​​of Valencia'!$C$518:$C$598,Datos!B55) -> 81 | I55: =COUNTIF('City ​​of Valencia'!$C$599:$C$772,Datos!B55) -> 174 | J55: =COUNTIF('City ​​of Valencia'!$C$773:$C$818,Datos!B55) -> 36 | K55: =COUNTIF('City ​​of Valencia'!$C$819:$C$823,Datos!B55) -> 0 | L55: =COUNTIF('City ​​of Valencia'!$C$824:$C$863,Datos!B55) -> 37 | M55: =COUNTIF('City ​​of Valencia'!$C$864:$C$952,Datos!B55) -> 79 | N55: 0 | O55: =COUNTIF('City ​​of Valencia'!$C$953:$C$976,Datos!B55) -> 0 | P55: =COUNTIF('City ​​of Valencia'!$C$977:$C$985,Datos!B55) -> 0 | Q55: =SUM(C55:P55) -> 777 | R55: 1º | S55: =Q55/$Q$60 -> 0.79124236
B56: Lockers | C56: =COUNTIF('City ​​of Valencia'!$C$4:$C$101,Datos!B56) -> 17 | D56: =COUNTIF('City ​​of Valencia'!$C$102:$C$133,Datos!B56) -> 28 | E56: =COUNTIF('City ​​of Valencia'!$C$134:$C$349,Datos!B56) -> 59 | F56: =COUNTIF('City ​​of Valencia'!$C$350:$C$460,Datos!B56) -> 19 | G56: =COUNTIF('City ​​of Valencia'!$C$461:$C$517,Datos!B56) -> 0 | H56: =COUNTIF('City ​​of Valencia'!$C$518:$C$598,Datos!B56) -> 0 | I56: =COUNTIF('City ​​of Valencia'!$C$599:$C$772,Datos!B56) -> 0 | J56: =COUNTIF('City ​​of Valencia'!$C$773:$C$818,Datos!B56) -> 0 | K56: =COUNTIF('City ​​of Valencia'!$C$819:$C$823,Datos!B56) -> 0 | L56: =COUNTIF('City ​​of Valencia'!$C$824:$C$863,Datos!B56) -> 0 | M56: =COUNTIF('City ​​of Valencia'!$C$864:$C$952,Datos!B56) -> 10 | N56: 0 | O56: =COUNTIF('City ​​of Valencia'!$C$953:$C$976,Datos!B56) -> 0 | P56: =COUNTIF('City ​​of Valencia'!$C$977:$C$985,Datos!B56) -> 0 | Q56: =SUM(C56:P56) -> 133 | R56: 2º | S56: =Q56/$Q$60 -> 0.13543788
B57: Click&Collect | C57: =COUNTIF('City ​​of Valencia'!$C$4:$C$101,Datos!B57) -> 0 | D57: =COUNTIF('City ​​of Valencia'!$C$102:$C$133,Datos!B57) -> 0 | E57: =COUNTIF('City ​​of Valencia'!$C$134:$C$349,Datos!B57) -> 0 | F57: =COUNTIF('City ​​of Valencia'!$C$350:$C$460,Datos!B57) -> 0 | G57: =COUNTIF('City ​​of Valencia'!$C$461:$C$517,Datos!B57) -> 0 | H57: =COUNTIF('City ​​of Valencia'!$C$518:$C$598,Datos!B57) -> 0 | I57: =COUNTIF('City ​​of Valencia'!$C$599:$C$772,Datos!B57) -> 0 | J57: =COUNTIF('City ​​of Valencia'!$C$773:$C$818,Datos!B57) -> 0 | K57: =COUNTIF('City ​​of Valencia'!$C$819:$C$823,Datos!B57) -> 0 | L57: =COUNTIF('City ​​of Valencia'!$C$824:$C$863,Datos!B57) -> 0 | M57: =COUNTIF('City ​​of Valencia'!$C$864:$C$952,Datos!B57) -> 0 | N57: 0 | O57: =COUNTIF('City ​​of Valencia'!$C$953:$C$976,Datos!B57) -> 24 | P57: =COUNTIF('City ​​of Valencia'!$C$977:$C$985,Datos!B57) -> 0 | Q57: =SUM(C57:P57) -> 24 | R57: 4º | S57: =Q57/$Q$60 -> 0.024439919
